Workbook

Sheet Dashboard
A1: Prospecting Dashboard
A2: Updates automatically from the Companies tab. Do not type on this tab.
A3: Key numbers
A4: Companies on list | B4: =COUNTA(Companies!$B$2:$B$7000) -> 5
A5: Emails sent (first email) | B5: =COUNT(Companies!$AG$2:$AG$7000) -> 0
A6: Replies | B6: =COUNTIFS(Companies!$AM$2:$AM$7000,"<>",Companies!$AM$2:$AM$7000,"<>No reply yet") -> 0
A7: Reply rate | B7: =IF(B5=0,0,B6/B5) -> 0
A8: Meetings booked | B8: =COUNTIF(Companies!$AN$2:$AN$7000,"Yes") -> 0
A9: Customers | B9: =COUNTIF(Companies!$C$2:$C$7000,"Customer") -> 0
A10: Follow-ups due today or overdue | B10: =SUMPRODUCT((Companies!$AH$2:$AH$7000<>"")*(N(+Companies!$AH$2:$AH$7000)<=TODAY())*((Companies!$AM$2:$AM$7000="")+(Companies!$AM$2:$AM$7000="No reply yet"))) -> 0
A11: Next steps due today or overdue | B11: =COUNTIFS(Companies!$AK$2:$AK$7000,"<="&TODAY(),Companies!$C$2:$C$7000,"<>Customer",Companies!$C$2:$C$7000,"<>Not a fit") -> 0
A14: Pipeline by Prospect Status
A15: Status | B15: Companies | C15: Tier A | D15: Tier B | E15: Tier C
A16: Not started | B16: =COUNTIF(Companies!$C$2:$C$7000,A16) -> 4 | C16: =COUNTIFS(Companies!$C$2:$C$7000,$A16,Companies!$D$2:$D$7000,"A") -> 1 | D16: =COUNTIFS(Companies!$C$2:$C$7000,$A16,Companies!$D$2:$D$7000,"B") -> 2 | E16: =COUNTIFS(Companies!$C$2:$C$7000,$A16,Companies!$D$2:$D$7000,"C") -> 1
A17: Needs research | B17: =COUNTIF(Companies!$C$2:$C$7000,A17) -> 0 | C17: =COUNTIFS(Companies!$C$2:$C$7000,$A17,Companies!$D$2:$D$7000,"A") -> 0 | D17: =COUNTIFS(Companies!$C$2:$C$7000,$A17,Companies!$D$2:$D$7000,"B") -> 0 | E17: =COUNTIFS(Companies!$C$2:$C$7000,$A17,Companies!$D$2:$D$7000,"C") -> 0
A18: Ready to email | B18: =COUNTIF(Companies!$C$2:$C$7000,A18) -> 1 | C18: =COUNTIFS(Companies!$C$2:$C$7000,$A18,Companies!$D$2:$D$7000,"A") -> 1 | D18: =COUNTIFS(Companies!$C$2:$C$7000,$A18,Companies!$D$2:$D$7000,"B") -> 0 | E18: =COUNTIFS(Companies!$C$2:$C$7000,$A18,Companies!$D$2:$D$7000,"C") -> 0
A19: Emailed | B19: =COUNTIF(Companies!$C$2:$C$7000,A19) -> 0 | C19: =COUNTIFS(Companies!$C$2:$C$7000,$A19,Companies!$D$2:$D$7000,"A") -> 0 | D19: =COUNTIFS(Companies!$C$2:$C$7000,$A19,Companies!$D$2:$D$7000,"B") -> 0 | E19: =COUNTIFS(Companies!$C$2:$C$7000,$A19,Companies!$D$2:$D$7000,"C") -> 0
A20: Following up | B20: =COUNTIF(Companies!$C$2:$C$7000,A20) -> 0 | C20: =COUNTIFS(Companies!$C$2:$C$7000,$A20,Companies!$D$2:$D$7000,"A") -> 0 | D20: =COUNTIFS(Companies!$C$2:$C$7000,$A20,Companies!$D$2:$D$7000,"B") -> 0 | E20: =COUNTIFS(Companies!$C$2:$C$7000,$A20,Companies!$D$2:$D$7000,"C") -> 0
A21: Replied | B21: =COUNTIF(Companies!$C$2:$C$7000,A21) -> 0 | C21: =COUNTIFS(Companies!$C$2:$C$7000,$A21,Companies!$D$2:$D$7000,"A") -> 0 | D21: =COUNTIFS(Companies!$C$2:$C$7000,$A21,Companies!$D$2:$D$7000,"B") -> 0 | E21: =COUNTIFS(Companies!$C$2:$C$7000,$A21,Companies!$D$2:$D$7000,"C") -> 0
A22: Meeting set | B22: =COUNTIF(Companies!$C$2:$C$7000,A22) -> 0 | C22: =COUNTIFS(Companies!$C$2:$C$7000,$A22,Companies!$D$2:$D$7000,"A") -> 0 | D22: =COUNTIFS(Companies!$C$2:$C$7000,$A22,Companies!$D$2:$D$7000,"B") -> 0 | E22: =COUNTIFS(Companies!$C$2:$C$7000,$A22,Companies!$D$2:$D$7000,"C") -> 0
A23: Customer | B23: =COUNTIF(Companies!$C$2:$C$7000,A23) -> 0 | C23: =COUNTIFS(Companies!$C$2:$C$7000,$A23,Companies!$D$2:$D$7000,"A") -> 0 | D23: =COUNTIFS(Companies!$C$2:$C$7000,$A23,Companies!$D$2:$D$7000,"B") -> 0 | E23: =COUNTIFS(Companies!$C$2:$C$7000,$A23,Companies!$D$2:$D$7000,"C") -> 0
A24: Not now | B24: =COUNTIF(Companies!$C$2:$C$7000,A24) -> 0 | C24: =COUNTIFS(Companies!$C$2:$C$7000,$A24,Companies!$D$2:$D$7000,"A") -> 0 | D24: =COUNTIFS(Companies!$C$2:$C$7000,$A24,Companies!$D$2:$D$7000,"B") -> 0 | E24: =COUNTIFS(Companies!$C$2:$C$7000,$A24,Companies!$D$2:$D$7000,"C") -> 0
A25: Not a fit | B25: =COUNTIF(Companies!$C$2:$C$7000,A25) -> 0 | C25: =COUNTIFS(Companies!$C$2:$C$7000,$A25,Companies!$D$2:$D$7000,"A") -> 0 | D25: =COUNTIFS(Companies!$C$2:$C$7000,$A25,Companies!$D$2:$D$7000,"B") -> 0 | E25: =COUNTIFS(Companies!$C$2:$C$7000,$A25,Companies!$D$2:$D$7000,"C") -> 0
A28: Results by Industry Group
A29: Industry Group | B29: Companies | C29: Emails sent | D29: Replies | E29: Reply rate | F29: Meetings | G29: Customers
A30: Metalworking & Machinery | B30: =COUNTIF(Companies!$F$2:$F$7000,A30) -> 1 | C30: =COUNTIFS(Companies!$F$2:$F$7000,A30,Companies!$AG$2:$AG$7000,"<>") -> 0 | D30: =COUNTIFS(Companies!$F$2:$F$7000,A30,Companies!$AM$2:$AM$7000,"<>",Companies!$AM$2:$AM$7000,"<>No reply yet") -> 0 | E30: =IF(C30=0,0,D30/C30) -> 0 | F30: =COUNTIFS(Companies!$F$2:$F$7000,A30,Companies!$AN$2:$AN$7000,"Yes") -> 0 | G30: =COUNTIFS(Companies!$F$2:$F$7000,A30,Companies!$C$2:$C$7000,"Customer") -> 0
A31: Construction | B31: =COUNTIF(Companies!$F$2:$F$7000,A31) -> 1 | C31: =COUNTIFS(Companies!$F$2:$F$7000,A31,Companies!$AG$2:$AG$7000,"<>") -> 0 | D31: =COUNTIFS(Companies!$F$2:$F$7000,A31,Companies!$AM$2:$AM$7000,"<>",Companies!$AM$2:$AM$7000,"<>No reply yet") -> 0 | E31: =IF(C31=0,0,D31/C31) -> 0 | F31: =COUNTIFS(Companies!$F$2:$F$7000,A31,Companies!$AN$2:$AN$7000,"Yes") -> 0 | G31: =COUNTIFS(Companies!$F$2:$F$7000,A31,Companies!$C$2:$C$7000,"Customer") -> 0
A32: Other Manufacturing | B32: =COUNTIF(Companies!$F$2:$F$7000,A32) -> 0 | C32: =COUNTIFS(Companies!$F$2:$F$7000,A32,Companies!$AG$2:$AG$7000,"<>") -> 0 | D32: =COUNTIFS(Companies!$F$2:$F$7000,A32,Companies!$AM$2:$AM$7000,"<>",Companies!$AM$2:$AM$7000,"<>No reply yet") -> 0 | E32: =IF(C32=0,0,D32/C32) -> 0 | F32: =COUNTIFS(Companies!$F$2:$F$7000,A32,Companies!$AN$2:$AN$7000,"Yes") -> 0 | G32: =COUNTIFS(Companies!$F$2:$F$7000,A32,Companies!$C$2:$C$7000,"Customer") -> 0
A33: Wholesale & Distribution | B33: =COUNTIF(Companies!$F$2:$F$7000,A33) -> 0 | C33: =COUNTIFS(Companies!$F$2:$F$7000,A33,Companies!$AG$2:$AG$7000,"<>") -> 0 | D33: =COUNTIFS(Companies!$F$2:$F$7000,A33,Companies!$AM$2:$AM$7000,"<>",Companies!$AM$2:$AM$7000,"<>No reply yet") -> 0 | E33: =IF(C33=0,0,D33/C33) -> 0 | F33: =COUNTIFS(Companies!$F$2:$F$7000,A33,Companies!$AN$2:$AN$7000,"Yes") -> 0 | G33: =COUNTIFS(Companies!$F$2:$F$7000,A33,Companies!$C$2:$C$7000,"Customer") -> 0
A34: Logistics & Transportation | B34: =COUNTIF(Companies!$F$2:$F$7000,A34) -> 1 | C34: =COUNTIFS(Companies!$F$2:$F$7000,A34,Companies!$AG$2:$AG$7000,"<>") -> 0 | D34: =COUNTIFS(Companies!$F$2:$F$7000,A34,Companies!$AM$2:$AM$7000,"<>",Companies!$AM$2:$AM$7000,"<>No reply yet") -> 0 | E34: =IF(C34=0,0,D34/C34) -> 0 | F34: =COUNTIFS(Companies!$F$2:$F$7000,A34,Companies!$AN$2:$AN$7000,"Yes") -> 0 | G34: =COUNTIFS(Companies!$F$2:$F$7000,A34,Companies!$C$2:$C$7000,"Customer") -> 0
A35: Plastics, Rubber & Chemicals | B35: =COUNTIF(Companies!$F$2:$F$7000,A35) -> 1 | C35: =COUNTIFS(Companies!$F$2:$F$7000,A35,Companies!$AG$2:$AG$7000,"<>") -> 0 | D35: =COUNTIFS(Companies!$F$2:$F$7000,A35,Companies!$AM$2:$AM$7000,"<>",Companies!$AM$2:$AM$7000,"<>No reply yet") -> 0 | E35: =IF(C35=0,0,D35/C35) -> 0 | F35: =COUNTIFS(Companies!$F$2:$F$7000,A35,Companies!$AN$2:$AN$7000,"Yes") -> 0 | G35: =COUNTIFS(Companies!$F$2:$F$7000,A35,Companies!$C$2:$C$7000,"Customer") -> 0
A36: Automotive & Aerospace | B36: =COUNTIF(Companies!$F$2:$F$7000,A36) -> 1 | C36: =COUNTIFS(Companies!$F$2:$F$7000,A36,Companies!$AG$2:$AG$7000,"<>") -> 0 | D36: =COUNTIFS(Companies!$F$2:$F$7000,A36,Companies!$AM$2:$AM$7000,"<>",Companies!$AM$2:$AM$7000,"<>No reply yet") -> 0 | E36: =IF(C36=0,0,D36/C36) -> 0 | F36: =COUNTIFS(Companies!$F$2:$F$7000,A36,Companies!$AN$2:$AN$7000,"Yes") -> 0 | G36: =COUNTIFS(Companies!$F$2:$F$7000,A36,Companies!$C$2:$C$7000,"Customer") -> 0
A37: Agriculture, Forestry & Landscaping | B37: =COUNTIF(Companies!$F$2:$F$7000,A37) -> 0 | C37: =COUNTIFS(Companies!$F$2:$F$7000,A37,Companies!$AG$2:$AG$7000,"<>") -> 0 | D37: =COUNTIFS(Companies!$F$2:$F$7000,A37,Companies!$AM$2:$AM$7000,"<>",Companies!$AM$2:$AM$7000,"<>No reply yet") -> 0 | E37: =IF(C37=0,0,D37/C37) -> 0 | F37: =COUNTIFS(Companies!$F$2:$F$7000,A37,Companies!$AN$2:$AN$7000,"Yes") -> 0 | G37: =COUNTIFS(Companies!$F$2:$F$7000,A37,Companies!$C$2:$C$7000,"Customer") -> 0
A38: Services, Repair & Staffing | B38: =COUNTIF(Companies!$F$2:$F$7000,A38) -> 0 | C38: =COUNTIFS(Companies!$F$2:$F$7000,A38,Companies!$AG$2:$AG$7000,"<>") -> 0 | D38: =COUNTIFS(Companies!$F$2:$F$7000,A38,Companies!$AM$2:$AM$7000,"<>",Companies!$AM$2:$AM$7000,"<>No reply yet") -> 0 | E38: =IF(C38=0,0,D38/C38) -> 0 | F38: =COUNTIFS(Companies!$F$2:$F$7000,A38,Companies!$AN$2:$AN$7000,"Yes") -> 0 | G38: =COUNTIFS(Companies!$F$2:$F$7000,A38,Companies!$C$2:$C$7000,"Customer") -> 0
A39: Healthcare | B39: =COUNTIF(Companies!$F$2:$F$7000,A39) -> 0 | C39: =COUNTIFS(Companies!$F$2:$F$7000,A39,Companies!$AG$2:$AG$7000,"<>") -> 0 | D39: =COUNTIFS(Companies!$F$2:$F$7000,A39,Companies!$AM$2:$AM$7000,"<>",Companies!$AM$2:$AM$7000,"<>No reply yet") -> 0 | E39: =IF(C39=0,0,D39/C39) -> 0 | F39: =COUNTIFS(Companies!$F$2:$F$7000,A39,Companies!$AN$2:$AN$7000,"Yes") -> 0 | G39: =COUNTIFS(Companies!$F$2:$F$7000,A39,Companies!$C$2:$C$7000,"Customer") -> 0
A40: Food Processing | B40: =COUNTIF(Companies!$F$2:$F$7000,A40) -> 0 | C40: =COUNTIFS(Companies!$F$2:$F$7000,A40,Companies!$AG$2:$AG$7000,"<>") -> 0 | D40: =COUNTIFS(Companies!$F$2:$F$7000,A40,Companies!$AM$2:$AM$7000,"<>",Companies!$AM$2:$AM$7000,"<>No reply yet") -> 0 | E40: =IF(C40=0,0,D40/C40) -> 0 | F40: =COUNTIFS(Companies!$F$2:$F$7000,A40,Companies!$AN$2:$AN$7000,"Yes") -> 0 | G40: =COUNTIFS(Companies!$F$2:$F$7000,A40,Companies!$C$2:$C$7000,"Customer") -> 0
A41: Public Sector & Municipal | B41: =COUNTIF(Companies!$F$2:$F$7000,A41) -> 0 | C41: =COUNTIFS(Companies!$F$2:$F$7000,A41,Companies!$AG$2:$AG$7000,"<>") -> 0 | D41: =COUNTIFS(Companies!$F$2:$F$7000,A41,Companies!$AM$2:$AM$7000,"<>",Companies!$AM$2:$AM$7000,"<>No reply yet") -> 0 | E41: =IF(C41=0,0,D41/C41) -> 0 | F41: =COUNTIFS(Companies!$F$2:$F$7000,A41,Companies!$AN$2:$AN$7000,"Yes") -> 0 | G41: =COUNTIFS(Companies!$F$2:$F$7000,A41,Companies!$C$2:$C$7000,"Customer") -> 0
... A44: Retail, Hospitality & Other | B44: =COUNTIF(Companies!$F$2:$F$7000,A44) -> 0 | C44: =COUNTIFS(Companies!$F$2:$F$7000,A44,Companies!$AG$2:$AG$7000,"<>") -> 0 | D44: =COUNTIFS(Companies!$F$2:$F$7000,A44,Companies!$AM$2:$AM$7000,"<>",Companies!$AM$2:$AM$7000,"<>No reply yet") -> 0 | E44: =IF(C44=0,0,D44/C44) -> 0 | F44: =COUNTIFS(Companies!$F$2:$F$7000,A44,Companies!$AN$2:$AN$7000,"Yes") -> 0 | G44: =COUNTIFS(Companies!$F$2:$F$7000,A44,Companies!$C$2:$C$7000,"Customer") -> 0
A47: A/B email test
A48: Email Version | B48: Emails sent | C48: Replies | D48: Reply rate | E48: Meetings
...

Sheet How to use
A1: How to use this CRM
A3: 1. Work in the Companies tab. One row = one company. Use the filter arrows in the header row to sort and filter (e.g. Tier = A, MI Region = West).
A4: 2. Column header colors tell you what to edit:
A5: Dark gray = OSHA data (filled in for you, leave as-is)
A6: Blue = company research you fill in (website, main phone, general email, contact research status)
A7: Green = Contact 1 and Contact 2 (name, title, role, email, phone)
A8: Orange = outreach tracking (status, email version, dates, reply, meeting, notes)
A9: 3. Dropdown cells: click the cell, then the small arrow. To change dropdown options, edit the Lists tab.
A10: 4. "Find Website" and "Find People (LinkedIn)" are clickable search links for each company.
A11: 5. Contact Research: Search online -> Call company -> Found - ready (or No contact found).
A12: 6. When you send the first email, type the date in First Email Sent (e.g. 10/28/2026). Follow-up 1 Due (+3 workdays) and Follow-up 2 Due (+7 workdays) fill in automatically and turn ORANGE when due and no reply yet.
A13: 7. Set Reply Type when someone answers, and update Prospect Status. Use Next Step + Next Step Date for calls, sample drop-offs and "Not now" recontact dates.
... A25: OSHA Injury Rate = recordable cases per 100 full-time workers per year. Injury numbers are for your background only - do not quote them in cold emails.

Sheet Companies
A1: ID | B1: Company | C1: Prospect Status | D1: Tier | E1: Glove Fit | F1: Industry Group | G1: Industry Detail | H1: MI Region | I1: City | J1: Street Address | K1: ZIP | L1: MI Employees | M1: MI Sites | N1: OSHA Recordable Cases | O1: OSHA Injury Rate | P1: Website | Q1: Find Website | R1: Find People (LinkedIn) | S1: Main Phone | T1: General Email | U1: Contact Research | V1: Contact 1 Name | W1: Contact 1 Title | X1: Contact 1 Role | Y1: Contact 1 Email | Z1: Contact 1 Phone | AA1: Contact 2 Name | AB1: Contact 2 Title | AC1: Contact 2 Role | AD1: Contact 2 Email | AE1: Contact 2 Phone | AF1: Email Version | AG1: First Email Sent | AH1: Follow-up 1 Due | AI1: Follow-up 2 Due | AJ1: Next Step | AK1: Next Step Date | AL1: Last Contact Date | AM1: Reply Type | AN1: Meeting Booked | AO1: Notes | AP1: In HubSpot | AQ1: Brief File | AR1: Recommended Styles | AS1: Call Opener | AT1: Safety Email Subject | AU1: Safety Email Body | AV1: Purchasing Email Subject | AW1: Purchasing Email Body | AX1: General Inbox Email Subject | AY1: General Inbox Email Body | AZ1: Follow-up 1 Body | BA1: Follow-up 2 Body | BB1: Voicemail | BC1: Generated On
A2: 1 | B2: Kestrel Lake Stamping Co. | C2: Ready to email | D2: A | E2: High | F2: Automotive & Aerospace | G2: Automotive - Parts Supplier | H2: West (Grand Rapids/Muskegon) | I2: Holland | J2: 100 Example Industrial Dr | K2: 49423 | L2: 820 | M2: 3 | N2: 41 | O2: 5.2 | Q2: Search | R2: Search | U2: Found - ready | V2: Alex Rivera | W2: EHS Manager | X2: Safety / EHS | Y2: alex.rivera@example.com | AF2: A - Pain point | AH2: =IF(AG2="","",WORKDAY(AG2,3)) | AI2: =IF(AG2="","",WORKDAY(AG2,7)) | AO2: FICTIONAL example row: a researched company with a named safety contact. | AP2: No | AQ2: briefs/generated/0001-kestrel-lake-stamping-co.md | AR2: 43001 (cut protection with grip on oily parts); 8846 (very thin cut F glove for assembly and inspection); WELDING 118A (welding cells) | AS2: In automotive, the fight is always cut protection versus dexterity, and that's the gap I help close. | AT2: Glove idea for Kestrel Lake Stamping | AU2: Hi Alex, Stamped edges and oily parts are one of the hardest places to keep gloves on, because a glove thick enough to stop a cut is often too clumsy for assembly. I'm the Michigan rep for Tegera gloves by Ejendals. For stamping, welding and assembly, I'd start with the TEGERA 43001 (cut protection with grip on oily parts) and the TEGERA 8846 (very thin cut F glove for assembly and inspection). Sizes go up to 12 in some styles, and they ship through Fastenal, MSC and other major distributors, so there's no new vendor. Would you be open to a 15-minute call to see if a glove trial at Kestrel Lake Stamping makes sense? Your Name Territory Sales Representative | Your Company (555) 555-0100 | you@yourcompany.com [Your business mailing address] Not the right person, or prefer no follow-ups? Just reply and let me know. | AV2: Glove spend at Kestrel Lake Stamping | AW2: Hi [First name], Gloves are a consumable that adds up fast in stamping, welding and assembly, especially when they wear out quickly or get tossed because they don't fit. I'm the Michigan rep for Tegera gloves by Ejendals. They're made to last longer at each protection level, which lowers what you spend per worker, and sizing goes up to 12 in some styles. You can order through Fastenal, MSC and other major distributors, so there's no new vendor setup. Would a 15-minute call make sense to compare what Kestrel Lake Stamping buys today? Your Name Territory Sales Representative | Your Company (555) 555-0100 | you@yourcompany.com [Your business mailing address] Not the right person, or prefer no follow-ups? Just reply and let me know. | AX2: Who handles safety gloves at Kestrel Lake Stamping? | AY2: Hi, I'm Your Name, the Michigan rep for Tegera safety gloves by Ejendals. Could you point me to the person who handles safety gloves or PPE purchasing for Kestrel Lake Stamping? Usually that's the safety manager or purchasing. I'd like to send them a short note about gloves for stamping, welding and assembly. Thank you! Your Name Territory Sales Representative | Your Company (555) 555-0100 | you@yourcompany.com [Your business mailing address] Not the right person, or prefer no follow-ups? Just reply and let me know. | AZ2: Hi [First name], Following up on my note about gloves for stamping, welding and assembly. If it's easier, I can drop off a few pairs of the TEGERA 43001 in different sizes so your team can try them on shift. Is there a good day this week or next? Your Name Territory Sales Representative | Your Company (555) 555-0100 | you@yourcompany.com [Your business mailing address] Not the right person, or prefer no follow-ups? Just reply and let me know. | BA2: Hi [First name], I don't want to crowd your inbox, so this is my last note for now. If gloves come up later, I'm local and happy to help. We also carry JALAS safety footwear from the same manufacturer. Your Name Territory Sales Representative | Your Company (555) 555-0100 | you@yourcompany.com [Your business mailing address] Not the right person, or prefer no follow-ups? Just reply and let me know. | BB2: Hi [First name], this is Your Name with Your Company, the Michigan rep for Tegera safety gloves. I'm calling about gloves for stamping, welding and assembly at Kestrel Lake Stamping. I'd like to drop off a few pairs of the TEGERA 43001 for your team to try. I'll send a short email too. You can reach me at (555) 555-0100. Again, Your Name, (555) 555-0100. Thanks. | BC2: 46323
A3: 2 | B3: Sablewood Molded Plastics | C3: Not started | D3: A | E3: High | F3: Plastics, Rubber & Chemicals | G3: Manufacturing - Plastics & Rubber | H3: Southeast (Detroit Metro) | I3: Sterling Heights | J3: 200 Sample Rd | K3: 48310 | L3: 410 | M3: 1 | N3: 22 | O3: 6 | Q3: Search | R3: Search | U3: Not started | AF3: B - News/trigger | AH3: =IF(AG3="","",WORKDAY(AG3,3)) | AI3: =IF(AG3="","",WORKDAY(AG3,7)) | AP3: No | AQ3: briefs/generated/0002-sablewood-molded-plastics.md | AR3: 43001 (cut protection for trimming and deflashing); Tegera chemical & liquid protection gloves (chemical and liquid handling); Tegera heat protection gloves (hot molds and heated materials) | AS3: Molding and chemical plants usually juggle cut, heat and chemical gloves, and I can cover all three with one line. | AT3: Local glove support for Sablewood Molded Plastics | AU3: Hi [First name], I'm guessing glove choices at your Sterling Heights location vary by area and shift, and some people skip them. I'm the Michigan rep for Tegera gloves by Ejendals, and I cover Southeast Michigan in person: plant walks, fit checks and glove trials. For molding, trimming and chemical handling, the TEGERA 43001 and Tegera chemical & liquid protection gloves are where I'd start, and you can order them through Fastenal, MSC and other major distributors. Would you be open to a 15-minute call, or a quick visit with samples? Your Name Territory Sales Representative | Your Company (555) 555-0100 | you@yourcompany.com [Your business mailing address] Not the right person, or prefer no follow-ups? Just reply and let me know. | AV3: Simplifying gloves at Sablewood Molded Plastics | AW3: Hi [First name], Most companies I visit buy several glove types from several sources, and nobody's sure which one actually lasts. I'm the Michigan rep for Tegera gloves by Ejendals. One line covers cut, heat, cold and wet work, and vibration, and it ships through Fastenal, MSC and other major distributors you may already use. Would a 15-minute call make sense to compare what you buy today? Your Name Territory Sales Representative | Your Company (555) 555-0100 | you@yourcompany.com [Your business mailing address] Not the right person, or prefer no follow-ups? Just reply and let me know. | AX3: Who handles safety gloves at Sablewood Molded Plastics? | AY3: Hi, I'm Your Name, the Michigan rep for Tegera safety gloves by Ejendals. Could you point me to the person who handles safety gloves or PPE purchasing for Sablewood Molded Plastics? Usually that's the safety manager or purchasing. I'd like to send them a short note about gloves for molding, trimming and chemical handling. Thank you! Your Name Territory Sales Representative | Your Company (555) 555-0100 | you@yourcompany.com [Your business mailing address] Not the right person, or prefer no follow-ups? Just reply and let me know. | AZ3: Hi [First name], Following up on my note about gloves for molding, trimming and chemical handling. If it's easier, I can drop off a few pairs of the TEGERA 43001 in different sizes so your team can try them on shift. Is there a good day this week or next? Your Name Territory Sales Representative | Your Company (555) 555-0100 | you@yourcompany.com [Your business mailing address] Not the right person, or prefer no follow-ups? Just reply and let me know. | BA3: Hi [First name], I don't want to crowd your inbox, so this is my last note for now. If gloves come up later, I'm local and happy to help. We also carry JALAS safety footwear from the same manufacturer. Your Name Territory Sales Representative | Your Company (555) 555-0100 | you@yourcompany.com [Your business mailing address] Not the right person, or prefer no follow-ups? Just reply and let me know. | BB3: Hi [First name], this is Your Name with Your Company, the Michigan rep for Tegera safety gloves. I'm calling about gloves for molding, trimming and chemical handling at Sablewood Molded Plastics. I'd like to drop off a few pairs of the TEGERA 43001 for your team to try. I'll send a short email too. You can reach me at (555) 555-0100. Again, Your Name, (555) 555-0100. Thanks. | BC3: 46323
A4: 3 | B4: Pinehaven Gray Iron | C4: Not started | D4: B | E4: High | F4: Metalworking & Machinery | G4: Manufacturing - Primary Metals/Foundry | H4: West (Grand Rapids/Muskegon) | I4: Muskegon | J4: 300 Demo Ave | K4: 49442 | L4: 180 | M4: 1 | N4: 19 | O4: 11.4 | Q4: Search | R4: Search | U4: Not started | AF4: A - Pain point | AH4: =IF(AG4="","",WORKDAY(AG4,3)) | AI4: =IF(AG4="","",WORKDAY(AG4,7)) | AP4: No | AQ4: briefs/generated/0003-pinehaven-gray-iron.md | AR4: 43001 (cut protection with grip on oily parts); 8846 (thin cut glove for inspection and fine work); PRO 9180A (grinding and deburring vibration) | AS4: Most machine and metal shops I talk to are fighting the same trade-off: cut protection versus feel. | AT4: Glove idea for Pinehaven Gray Iron | AU4: Hi [First name], Sharp parts and oily surfaces are hard on gloves, and a glove thick enough to stop a cut is often too clumsy for precise work. I'm the Michigan rep for Tegera gloves by Ejendals. For machining, grinding and handling sharp metal parts, I'd start with the TEGERA 43001 (cut protection with grip on oily parts) and the TEGERA 8846 (thin cut glove for inspection and fine work). Sizes go up to 12 in some styles, and they ship through Fastenal, MSC and other major distributors, so there's no new vendor. Would you be open to a 15-minute call to see if a glove trial at Pinehaven Gray Iron makes sense? Your Name Territory Sales Representative | Your Company (555) 555-0100 | you@yourcompany.com [Your business mailing address] Not the right person, or prefer no follow-ups? Just reply and let me know. | AV4: Glove spend at Pinehaven Gray Iron | AW4: Hi [First name], Gloves are a consumable that adds up fast in machining, grinding and handling sharp metal parts, especially when they wear out quickly or get tossed because they don't fit. I'm the Michigan rep for Tegera gloves by Ejendals. They're made to last longer at each protection level, which lowers what you spend per worker, and sizing goes up to 12 in some styles. You can order through Fastenal, MSC and other major distributors, so there's no new vendor setup. Would a 15-minute call make sense to compare what Pinehaven Gray Iron buys today? Your Name Territory Sales Representative | Your Company (555) 555-0100 | you@yourcompany.com [Your business mailing address] Not the right person, or prefer no follow-ups? Just reply and let me know. | AX4: Who handles safety gloves at Pinehaven Gray Iron? | AY4: Hi, I'm Your Name, the Michigan rep for Tegera safety gloves by Ejendals. Could you point me to the person who handles safety gloves or PPE purchasing for Pinehaven Gray Iron? Usually that's the safety manager or purchasing. I'd like to send them a short note about gloves for machining, grinding and handling sharp metal parts. Thank you! Your Name Territory Sales Representative | Your Company (555) 555-0100 | you@yourcompany.com [Your business mailing address] Not the right person, or prefer no follow-ups? Just reply and let me know. | AZ4: Hi [First name], Following up on my note about gloves for machining, grinding and handling sharp metal parts. If it's easier, I can drop off a few pairs of the TEGERA 43001 in different sizes so your team can try them on shift. Is there a good day this week or next? Your Name Territory Sales Representative | Your Company (555) 555-0100 | you@yourcompany.com [Your business mailing address] Not the right person, or prefer no follow-ups? Just reply and let me know. | BA4: Hi [First name], I don't want to crowd your inbox, so this is my last note for now. If gloves come up later, I'm local and happy to help. We also carry JALAS safety footwear from the same manufacturer. Your Name Territory Sales Representative | Your Company (555) 555-0100 | you@yourcompany.com [Your business mailing address] Not the right person, or prefer no follow-ups? Just reply and let me know. | BB4: Hi [First name], this is Your Name with Your Company, the Michigan rep for Tegera safety gloves. I'm calling about gloves for machining, grinding and handling sharp metal parts at Pinehaven Gray Iron. I'd like to drop off a few pairs of the TEGERA 43001 for your team to try. I'll send a short email too. You can reach me at (555) 555-0100. Again, Your Name, (555) 555-0100. Thanks. | BC4: 46323
A5: 4 | B5: Copperline Cold Storage & Logistics | C5: Not started | D5: B | E5: High | F5: Logistics & Transportation | G5: Logistics/Warehousing | H5: Saginaw / Bay / Thumb | I5: Saginaw | J5: 400 Placeholder St | K5: 48601 | L5: 150 | M5: 2 | N5: 12 | O5: 8.1 | Q5: Search | R5: Search | U5: Not started | AF5: B - News/trigger | AH5: =IF(AG5="","",WORKDAY(AG5,3)) | AI5: =IF(AG5="","",WORKDAY(AG5,7)) | AP5: No | AQ5: briefs/generated/0004-copperline-cold-storage-logistics.md | AR5: 295 (waterproof leather for cold, wet work); 43001 (cut protection with good grip) | AS5: With winter coming, this is when dock and yard crews start asking for better gloves. | AT5: Local glove support for Copperline Cold Storage & Logistics | AU5: Hi [First name], With Michigan winter on the way, cold, wet hands are about to become the main reason gloves come off. I'm the Michigan rep for Tegera gloves by Ejendals, and I cover the Saginaw, Bay City and Thumb area in person: plant walks, fit checks and glove trials. For drivers, dock and yard crews, the TEGERA 295 and TEGERA 43001 are where I'd start, and you can order them through Fastenal, MSC and other major distributors. Would you be open to a 15-minute call, or a quick visit with samples? Your Name Territory Sales Representative | Your Company (555) 555-0100 | you@yourcompany.com [Your business mailing address] Not the right person, or prefer no follow-ups? Just reply and let me know. | AV5: Simplifying gloves at Copperline Cold Storage & Logistics | AW5: Hi [First name], Buying gloves for 2 Michigan sites usually means different gloves, prices and reorder points at each one. I'm the Michigan rep for Tegera gloves by Ejendals. One line covers cut, heat, cold and wet work, and vibration, and it ships through Fastenal, MSC and other major distributors you may already use. Would a 15-minute call make sense to compare what you buy today? Your Name Territory Sales Representative | Your Company (555) 555-0100 | you@yourcompany.com [Your business mailing address] Not the right person, or prefer no follow-ups? Just reply and let me know. | AX5: Who handles safety gloves at Copperline Cold Storage & Logistics? | AY5: Hi, I'm Your Name, the Michigan rep for Tegera safety gloves by Ejendals. Could you point me to the person who handles safety gloves or PPE purchasing for Copperline Cold Storage & Logistics? Usually that's the safety manager or purchasing. I'd like to send them a short note about gloves for drivers, dock and yard crews. Thank you! Your Name Territory Sales Representative | Your Company (555) 555-0100 | you@yourcompany.com [Your business mailing address] Not the right person, or prefer no follow-ups? Just reply and let me know. | AZ5: Hi [First name], Following up on my note about gloves for drivers, dock and yard crews. If it's easier, I can drop off a few pairs of the TEGERA 295 in different sizes so your team can try them on shift. Is there a good day this week or next? Your Name Territory Sales Representative | Your Company (555) 555-0100 | you@yourcompany.com [Your business mailing address] Not the right person, or prefer no follow-ups? Just reply and let me know. | BA5: Hi [First name], I don't want to crowd your inbox, so this is my last note for now. If gloves come up later, I'm local and happy to help. We also carry JALAS safety footwear from the same manufacturer. Your Name Territory Sales Representative | Your Company (555) 555-0100 | you@yourcompany.com [Your business mailing address] Not the right person, or prefer no follow-ups? Just reply and let me know. | BB5: Hi [First name], this is Your Name with Your Company, the Michigan rep for Tegera safety gloves. I'm calling about gloves for drivers, dock and yard crews at Copperline Cold Storage & Logistics. I'd like to drop off a few pairs of the TEGERA 295 for your team to try. I'll send a short email too. You can reach me at (555) 555-0100. Again, Your Name, (555) 555-0100. Thanks. | BC5: 46323
A6: 5 | B6: Northvale Builders | C6: Not started | D6: C | E6: High | F6: Construction | G6: Construction - Concrete & Foundation | H6: Lansing / Mid-Michigan | I6: Lansing | J6: 500 Mock Ln | K6: 48906 | L6: 64 | M6: 1 | N6: 4 | O6: 6.3 | Q6: Search | R6: Search | U6: Not started | AF6: A - Pain point | AH6: =IF(AG6="","",WORKDAY(AG6,3)) | AI6: =IF(AG6="","",WORKDAY(AG6,7)) | AP6: No | AQ6: briefs/generated/0005-northvale-builders.md | AR6: 295 (waterproof leather for cold, wet jobsites); 43001 (cut protection for sheet metal and rebar); PRO 9180A (vibration from breakers and hammer drills) | AS6: With winter coming, this is when crews start complaining about cold, wet gloves. | AT6: Glove idea for Northvale Builders | AU6: Hi [First name], Construction gloves take a beating from concrete, rebar and weather, and crews go through them fast or skip them when they're wet and cold. I'm the Michigan rep for Tegera gloves by Ejendals. For outdoor construction crews, I'd start with the TEGERA 295 (waterproof leather for cold, wet jobsites) and the TEGERA 43001 (cut protection for sheet metal and rebar). Sizes go up to 12 in some styles, and they ship through Fastenal, MSC and other major distributors, so there's no new vendor. Would you be open to a 15-minute call to see if a glove trial at Northvale Builders makes sense? Your Name Territory Sales Representative | Your Company (555) 555-0100 | you@yourcompany.com [Your business mailing address] Not the right person, or prefer no follow-ups? Just reply and let me know. | AV6: Glove spend at Northvale Builders | AW6: Hi [First name], Gloves are a consumable that adds up fast in outdoor construction crews, especially when they wear out quickly or get tossed because they don't fit. I'm the Michigan rep for Tegera gloves by Ejendals. They're made to last longer at each protection level, which lowers what you spend per worker, and sizing goes up to 12 in some styles. You can order through Fastenal, MSC and other major distributors, so there's no new vendor setup. Would a 15-minute call make sense to compare what Northvale Builders buys today? Your Name Territory Sales Representative | Your Company (555) 555-0100 | you@yourcompany.com [Your business mailing address] Not the right person, or prefer no follow-ups? Just reply and let me know. | AX6: Who handles safety gloves at Northvale Builders? | AY6: Hi, I'm Your Name, the Michigan rep for Tegera safety gloves by Ejendals. Could you point me to the person who handles safety gloves or PPE purchasing for Northvale Builders? Usually that's the safety manager or purchasing. I'd like to send them a short note about gloves for outdoor construction crews. Thank you! Your Name Territory Sales Representative | Your Company (555) 555-0100 | you@yourcompany.com [Your business mailing address] Not the right person, or prefer no follow-ups? Just reply and let me know. | AZ6: Hi [First name], Following up on my note about gloves for outdoor construction crews. If it's easier, I can drop off a few pairs of the TEGERA 295 in different sizes so your team can try them on shift. Is there a good day this week or next? Your Name Territory Sales Representative | Your Company (555) 555-0100 | you@yourcompany.com [Your business mailing address] Not the right person, or prefer no follow-ups? Just reply and let me know. | BA6: Hi [First name], I don't want to crowd your inbox, so this is my last note for now. If gloves come up later, I'm local and happy to help. We also carry JALAS safety footwear from the same manufacturer. Your Name Territory Sales Representative | Your Company (555) 555-0100 | you@yourcompany.com [Your business mailing address] Not the right person, or prefer no follow-ups? Just reply and let me know. | BB6: Hi [First name], this is Your Name with Your Company, the Michigan rep for Tegera safety gloves. I'm calling about gloves for outdoor construction crews at Northvale Builders. I'd like to drop off a few pairs of the TEGERA 295 for your team to try. I'll send a short email too. You can reach me at (555) 555-0100. Again, Your Name, (555) 555-0100. Thanks. | BC6: 46323

Sheet Lists
A1: Prospect Status | B1: Tier | C1: Glove Fit | D1: Industry Group | E1: MI Region | F1: Contact Research | G1: Contact Role | H1: Email Version | I1: Next Step | J1: Reply Type | K1: Yes/No
A2: Not started | B2: A | C2: High | D2: Metalworking & Machinery | E2: Southeast (Detroit Metro) | F2: Not started | G2: Safety / EHS | H2: A - Pain point | I2: Call | J2: No reply yet | K2: Yes
A3: Needs research | B3: B | C3: Medium | D3: Construction | E3: West (Grand Rapids/Muskegon) | F3: Search online | G3: Purchasing | H3: B - News/trigger | I3: Email | J3: Positive | K3: No
A4: Ready to email | B4: C | C4: Low | D4: Other Manufacturing | E4: Southwest (Kalamazoo/Battle Creek) | F4: Call company | G4: Plant / Operations Mgr | I4: Call + Email | J4: Not now
A5: Emailed | D5: Wholesale & Distribution | E5: Lansing / Mid-Michigan | F5: Found - ready | G5: Owner / Executive | I5: Sample drop-off | J5: Not a fit
A6: Following up | D6: Logistics & Transportation | E6: Saginaw / Bay / Thumb | F6: No contact found | G6: HR | I6: Meeting | J6: Referral
A7: Replied | D7: Plastics, Rubber & Chemicals | E7: Flint / Genesee | G7: Maintenance | I7: None
A8: Meeting set | D8: Automotive & Aerospace | E8: Upper Peninsula | G8: Office / Reception
A9: Customer | D9: Agriculture, Forestry & Landscaping | E9: Jackson / South Central | G9: Other
A10: Not now | D10: Services, Repair & Staffing | E10: Northwest (Traverse City)
A11: Not a fit | D11: Healthcare | E11: Northern Lower
D12: Food Processing | E12: Unknown
D13: Public Sector & Municipal
D14: Waste & Recycling
D15: Energy, Utilities & Mining
D16: Retail, Hospitality & Other
